2022-03-31 00:51:46 | DEBUG | osdt initialized, invoked by: C:\Users\17074\AppData\Local\Programs\Python\Python38\Scripts\osdt 'run', 'osdt_examples\\osdt_testing\\runtests.py' | toolbox.py:352
2022-03-31 00:51:46 | INFO  | final format | toolbox.py:353
2022-03-31 00:51:46 | INFO  | created new system: ball <osdt.system.System object at 0x000001CBB61D6130> | system.py:117
2022-03-31 00:51:46 | INFO  | system added to environment: ball <osdt.system.System object at 0x000001CBB61D6130> | environment.py:76
2022-03-31 00:51:46 | INFO  | pre-move: D:\osdt_dev\osdt_home\osdt_output\runtests_main_2022_03_31_00_51_45_692328\osdt_log.txt | runtests.py:46
2022-03-31 00:51:46 | INFO  | changing output path: D:\osdt_dev\osdt_home\osdt_output\runtests_main_2022_03_31_00_51_45_692328 -> D:\osdt_dev\osdt_home\osdt_examples\osdt_testing\files | arguments.py:55
2022-03-31 00:51:46 | DEBUG | log file updated: D:\osdt_dev\osdt_home\osdt_output\runtests_main_2022_03_31_00_51_45_692328\osdt_log.txt -> D:\osdt_dev\osdt_home\osdt_examples\osdt_testing\files\osdt_log.txt | arguments.py:49
2022-03-31 00:51:46 | INFO  | running unit tests | runtests.py:15
2022-03-31 00:51:46 | ERROR | failed to run osdt_examples\osdt_testing\runtests.py
Traceback (most recent call last):
  File "c:\users\17074\documents\github\osdt_dev\osdt\cli.py", line 263, in run_function
    function(**func_args)
  File "D:\osdt_dev\osdt_home\osdt_examples\osdt_testing\runtests.py", line 49, in main
    report=run_tests(*fileio_tests.TESTS)
  File "D:\osdt_dev\osdt_home\osdt_examples\osdt_testing\runtests.py", line 22, in run_tests
    s.addTests(test_case)
  File "C:\Users\17074\AppData\Local\Programs\Python\Python38\lib\unittest\suite.py", line 57, in addTests
    for test in tests:
TypeError: 'type' object is not iterable
 | cli.py:265
