2022-03-31 11:10:28 | INFO  | 



D:\osdt_dev\osdt_home



 | user.py:189
2022-03-31 11:10:28 | INFO  | 



C:\Users\17074\AppData\Local\osdt\osdt\osdt_workspace



 | user.py:189
2022-03-31 11:10:28 | INFO  | 



C:\Users\17074\GitHub\osdt_documentation



 | user.py:189
2022-03-31 11:10:28 | INFO  | 



D:\osdt_dev\test_path



 | user.py:189
2022-03-31 11:10:28 | DEBUG | osdt initialized [python tester.py --date --log] | toolbox.py:350
2022-03-31 11:10:28 | INFO  | toggling user data: False | user.py:629
2022-03-31 11:10:28 | INFO  | removing: C:\Users\17074\AppData\Local\osdt\osdt\osdt_workspace | user.py:301
2022-03-31 11:10:28 | INFO  | removing: D:\osdt_dev\osdt_home | user.py:301
2022-03-31 11:10:28 | INFO  | removing: C:\Users\17074\GitHub\osdt_documentation | user.py:301
2022-03-31 11:10:28 | INFO  | removing: D:\osdt_dev\test_path | user.py:301
2022-03-31 11:10:28 | INFO  | test root: D:\osdt_dev\osdt_home\osdt_examples\osdt_testing | tester.py:178
2022-03-31 11:10:28 | INFO  | changing output path: D:\osdt_dev\osdt_home\osdt_output\_operations\python -> D:\osdt_dev\osdt_home\osdt_examples\osdt_testing\files | arguments.py:44
2022-03-31 11:10:28 | DEBUG | log file updated: D:\osdt_dev\osdt_home\osdt_output\_operations\python\osdt_log.txt -> D:\osdt_dev\osdt_home\osdt_examples\osdt_testing\files\osdt_log.txt | logger.py:29
2022-03-31 11:10:28 | INFO  | 

################################################################################
Test Log
################################################################################

 | tester.py:169
2022-03-31 11:10:28 | INFO  | toggling user data: False | user.py:629
2022-03-31 11:10:28 | INFO  | created new system: ball <osdt.system.System object at 0x000001EDBFA2B1F0> | system.py:117
2022-03-31 11:10:28 | INFO  | system added to environment: ball <osdt.system.System object at 0x000001EDBFA2B1F0> | environment.py:76
2022-03-31 11:10:28 | INFO  | testing: environment_tests | tester.py:111
2022-03-31 11:10:28 | INFO  | test_add_duplicates (environment_tests.SystemTests) ... ERROR | tester.py:94
2022-03-31 11:10:28 | INFO  | test_add_systems (environment_tests.SystemTests) ... ERROR | tester.py:94
2022-03-31 11:10:28 | INFO  | test_auto_add_systems (environment_tests.SystemTests) ... ERROR | tester.py:94
2022-03-31 11:10:28 | INFO  | ====================================================================== | tester.py:94
2022-03-31 11:10:28 | INFO  | ERROR: test_add_duplicates (environment_tests.SystemTests) | tester.py:94
2022-03-31 11:10:28 | INFO  | ---------------------------------------------------------------------- | tester.py:94
2022-03-31 11:10:28 | INFO  | Traceback (most recent call last):
  File "D:\osdt_dev\osdt_home\osdt_examples\osdt_testing\tests\environment_tests.py", line 21, in setUp
    osdt.enable_user_data(False)
AttributeError: module 'osdt' has no attribute 'enable_user_data' | tester.py:94
2022-03-31 11:10:28 | INFO  | ====================================================================== | tester.py:94
2022-03-31 11:10:28 | INFO  | ERROR: test_add_systems (environment_tests.SystemTests) | tester.py:94
2022-03-31 11:10:28 | INFO  | ---------------------------------------------------------------------- | tester.py:94
2022-03-31 11:10:28 | INFO  | Traceback (most recent call last):
  File "D:\osdt_dev\osdt_home\osdt_examples\osdt_testing\tests\environment_tests.py", line 21, in setUp
    osdt.enable_user_data(False)
AttributeError: module 'osdt' has no attribute 'enable_user_data' | tester.py:94
2022-03-31 11:10:28 | INFO  | ====================================================================== | tester.py:94
2022-03-31 11:10:28 | INFO  | ERROR: test_auto_add_systems (environment_tests.SystemTests) | tester.py:94
2022-03-31 11:10:28 | INFO  | ---------------------------------------------------------------------- | tester.py:94
2022-03-31 11:10:28 | INFO  | Traceback (most recent call last):
  File "D:\osdt_dev\osdt_home\osdt_examples\osdt_testing\tests\environment_tests.py", line 21, in setUp
    osdt.enable_user_data(False)
AttributeError: module 'osdt' has no attribute 'enable_user_data' | tester.py:94
2022-03-31 11:10:28 | INFO  | ---------------------------------------------------------------------- | tester.py:94
2022-03-31 11:10:28 | INFO  | Ran 3 tests in 0.001s | tester.py:94
2022-03-31 11:10:28 | INFO  | FAILED (errors=3) | tester.py:94
2022-03-31 11:10:28 | INFO  | testing: fileio_tests | tester.py:111
2022-03-31 11:10:28 | INFO  | system added to environment: ball <osdt.system.System object at 0x000001EDBFA2B1F0> | environment.py:76
2022-03-31 11:10:28 | INFO  | exported object to yaml: GeneralConfiguration -> D:\osdt_dev\osdt_home\osdt_examples\osdt_testing\files\files\saved_env\config.yaml | fileio.py:235
2022-03-31 11:10:28 | INFO  | exported configuration to D:\osdt_dev\osdt_home\osdt_examples\osdt_testing\files\files/saved_env\config.yaml | fileio.py:77
2022-03-31 11:10:28 | INFO  | saved object to file: <osdt.system.System object at 0x000001EDBFA2B1F0> -> D:\osdt_dev\osdt_home\osdt_examples\osdt_testing\files\files\saved_env\sys_ball.odst | fileio.py:60
2022-03-31 11:10:28 | INFO  | exported object to yaml: dict -> D:\osdt_dev\osdt_home\osdt_examples\osdt_testing\files\files\saved_env\environment.yaml | fileio.py:235
2022-03-31 11:10:28 | INFO  | test_save_env (fileio_tests.SaveTests) ... ok | tester.py:94
2022-03-31 11:10:28 | INFO  | saved object to file: <osdt.system.System object at 0x000001EDBFA2B1F0> -> D:\osdt_dev\osdt_home\osdt_examples\osdt_testing\files\files\saved_obj.odst | fileio.py:60
2022-03-31 11:10:28 | INFO  | test_save_obj (fileio_tests.SaveTests) ... ok | tester.py:94
2022-03-31 11:10:28 | INFO  | loaded object from file: D:\osdt_dev\osdt_home\osdt_examples\osdt_testing\files\files\saved_env\sys_ball.odst -> <osdt.system.System object at 0x000001EDBF998F10> | fileio.py:169
2022-03-31 11:10:28 | INFO  | system added to environment: ball <osdt.system.System object at 0x000001EDBF998F10> | environment.py:76
2022-03-31 11:10:28 | INFO  | loaded environment system: ball <osdt.system.System object at 0x000001EDBF998F10> | environment.py:362
2022-03-31 11:10:28 | INFO  | loading configuration: D:\osdt_dev\osdt_home\osdt_examples\osdt_testing\files\files\saved_env\config.yaml | fileio.py:188
2022-03-31 11:10:28 | INFO  | environment loaded successfully from file: D:\osdt_dev\osdt_home\osdt_examples\osdt_testing\files\files\saved_env -> <osdt.environment.Environment object at 0x000001EDBF992940> | fileio.py:123
2022-03-31 11:10:28 | INFO  | test_load_env (fileio_tests.LoadTests) ... ok | tester.py:94
2022-03-31 11:10:28 | INFO  | loaded object from file: D:\osdt_dev\osdt_home\osdt_examples\osdt_testing\files\files\saved_obj.odst -> <osdt.system.System object at 0x000001EDBFA67460> | fileio.py:169
2022-03-31 11:10:28 | WARN  | duplicate id found - updating original id to include index: ball -> ball_1 (<osdt.system.System object at 0x000001EDBF998F10>) | environment.py:226
2022-03-31 11:10:28 | WARN  | updating duplicate system id: ball -> ball_2 (<osdt.system.System object at 0x000001EDBFA67460>) | environment.py:233
2022-03-31 11:10:28 | INFO  | system added to environment: ball_2 <osdt.system.System object at 0x000001EDBFA67460> | environment.py:76
2022-03-31 11:10:28 | INFO  | test_load_obj (fileio_tests.LoadTests) ... ok | tester.py:94
2022-03-31 11:10:28 | INFO  | loaded object from file: D:\osdt_dev\osdt_home\osdt_examples\osdt_testing\files\files\saved_env\sys_ball.odst -> <osdt.system.System object at 0x000001EDBFA67FD0> | fileio.py:169
2022-03-31 11:10:28 | INFO  | system added to environment: ball <osdt.system.System object at 0x000001EDBFA67FD0> | environment.py:76
2022-03-31 11:10:28 | INFO  | loaded environment system: ball <osdt.system.System object at 0x000001EDBFA67FD0> | environment.py:362
2022-03-31 11:10:28 | INFO  | loading configuration: D:\osdt_dev\osdt_home\osdt_examples\osdt_testing\files\files\saved_env\config.yaml | fileio.py:188
2022-03-31 11:10:28 | INFO  | environment loaded successfully from file: D:\osdt_dev\osdt_home\osdt_examples\osdt_testing\files\files\saved_env -> <osdt.environment.Environment object at 0x000001EDBFA2BDC0> | fileio.py:123
2022-03-31 11:10:28 | INFO  | test_load_env (fileio_tests.LoadTestsBad) ... FAIL | tester.py:94
2022-03-31 11:10:28 | INFO  | loaded object from file: D:\osdt_dev\osdt_home\osdt_examples\osdt_testing\files\files\saved_obj.odst -> <osdt.system.System object at 0x000001EDBF998B80> | fileio.py:169
2022-03-31 11:10:28 | WARN  | duplicate id found - updating original id to include index: ball -> ball_1 (<osdt.system.System object at 0x000001EDBFA67FD0>) | environment.py:226
2022-03-31 11:10:28 | WARN  | updating duplicate system id: ball -> ball_2 (<osdt.system.System object at 0x000001EDBF998B80>) | environment.py:233
2022-03-31 11:10:28 | INFO  | system added to environment: ball_2 <osdt.system.System object at 0x000001EDBF998B80> | environment.py:76
2022-03-31 11:10:28 | INFO  | test_load_obj (fileio_tests.LoadTestsBad) ... FAIL | tester.py:94
2022-03-31 11:10:28 | INFO  | ====================================================================== | tester.py:94
2022-03-31 11:10:28 | INFO  | FAIL: test_load_env (fileio_tests.LoadTestsBad) | tester.py:94
2022-03-31 11:10:28 | INFO  | ---------------------------------------------------------------------- | tester.py:94
2022-03-31 11:10:28 | INFO  | Traceback (most recent call last):
  File "D:\osdt_dev\osdt_home\osdt_examples\osdt_testing\tests\fileio_tests.py", line 65, in test_load_env
    self.compare_states(ball_state2, sys1.x())
  File "D:\osdt_dev\osdt_home\osdt_examples\osdt_testing\tests\fileio_tests.py", line 53, in compare_states
    self.assertEqual(orig.__dict__[key], loaded.__dict__[key])
AssertionError: 999.99 != 1.0 | tester.py:94
2022-03-31 11:10:28 | INFO  | ====================================================================== | tester.py:94
2022-03-31 11:10:28 | INFO  | FAIL: test_load_obj (fileio_tests.LoadTestsBad) | tester.py:94
2022-03-31 11:10:28 | INFO  | ---------------------------------------------------------------------- | tester.py:94
2022-03-31 11:10:28 | INFO  | Traceback (most recent call last):
  File "D:\osdt_dev\osdt_home\osdt_examples\osdt_testing\tests\fileio_tests.py", line 59, in test_load_obj
    self.compare_states(orig,loaded)
  File "D:\osdt_dev\osdt_home\osdt_examples\osdt_testing\tests\fileio_tests.py", line 53, in compare_states
    self.assertEqual(orig.__dict__[key], loaded.__dict__[key])
AssertionError: 43243.0 != 1.0 | tester.py:94
2022-03-31 11:10:28 | INFO  | ---------------------------------------------------------------------- | tester.py:94
2022-03-31 11:10:28 | INFO  | Ran 6 tests in 0.041s | tester.py:94
2022-03-31 11:10:28 | INFO  | FAILED (failures=2) | tester.py:94
2022-03-31 11:10:28 | INFO  | testing: user_tests | tester.py:111
2022-03-31 11:10:28 | INFO  | toggling user data: True | user.py:629
2022-03-31 11:10:28 | DEBUG | reloading user data | user.py:169
2022-03-31 11:10:28 | DEBUG | reconfiguring logger | logger.py:33
2022-03-31 11:10:28 | INFO  | 



D:\osdt_dev\osdt_home



 | user.py:189
2022-03-31 11:10:28 | INFO  | 



C:\Users\17074\AppData\Local\osdt\osdt\osdt_workspace



 | user.py:189
2022-03-31 11:10:28 | INFO  | 



C:\Users\17074\GitHub\osdt_documentation



 | user.py:189
2022-03-31 11:10:28 | INFO  | 



D:\osdt_dev\test_path



 | user.py:189
2022-03-31 11:10:28 | INFO  | toggling user data: False | user.py:629
2022-03-31 11:10:28 | INFO  | removing: C:\Users\17074\AppData\Local\osdt\osdt\osdt_workspace | user.py:301
2022-03-31 11:10:28 | INFO  | removing: D:\osdt_dev\osdt_home | user.py:301
2022-03-31 11:10:28 | INFO  | removing: C:\Users\17074\GitHub\osdt_documentation | user.py:301
2022-03-31 11:10:28 | INFO  | removing: D:\osdt_dev\test_path | user.py:301
2022-03-31 11:10:28 | INFO  | ['D:\\osdt_dev\\osdt_home', 'C:\\Users\\17074\\AppData\\Local\\osdt\\osdt\\osdt_workspace', 'C:\\Users\\17074\\GitHub\\osdt_documentation', 'D:\\osdt_dev\\test_path'] | user_tests.py:42
2022-03-31 11:10:28 | INFO  | toggling user data: True | user.py:629
2022-03-31 11:10:28 | DEBUG | reloading user data | user.py:169
2022-03-31 11:10:28 | DEBUG | reconfiguring logger | logger.py:33
2022-03-31 11:10:28 | INFO  | 



D:\osdt_dev\osdt_home



 | user.py:189
2022-03-31 11:10:28 | INFO  | 



C:\Users\17074\AppData\Local\osdt\osdt\osdt_workspace



 | user.py:189
2022-03-31 11:10:28 | INFO  | 



C:\Users\17074\GitHub\osdt_documentation



 | user.py:189
2022-03-31 11:10:28 | INFO  | 



D:\osdt_dev\test_path



 | user.py:189
2022-03-31 11:10:28 | INFO  | test_auto_add_systems (user_tests.SystemTests) ... ok | tester.py:94
2022-03-31 11:10:28 | INFO  | toggling user data: False | user.py:629
2022-03-31 11:10:28 | INFO  | removing: C:\Users\17074\AppData\Local\osdt\osdt\osdt_workspace | user.py:301
2022-03-31 11:10:28 | INFO  | removing: D:\osdt_dev\osdt_home | user.py:301
2022-03-31 11:10:28 | INFO  | removing: C:\Users\17074\GitHub\osdt_documentation | user.py:301
2022-03-31 11:10:28 | INFO  | removing: D:\osdt_dev\test_path | user.py:301
2022-03-31 11:10:28 | DEBUG | reconfiguring logger | logger.py:33
2022-03-31 11:10:28 | INFO  | 



files\not_on_path



 | user.py:189
2022-03-31 11:10:28 | INFO  | test_manual_user_data_path (user_tests.SystemTests) ... ok | tester.py:94
2022-03-31 11:10:28 | INFO  | ---------------------------------------------------------------------- | tester.py:94
2022-03-31 11:10:28 | INFO  | Ran 2 tests in 0.045s | tester.py:94
2022-03-31 11:10:28 | INFO  | OK | tester.py:94
2022-03-31 11:10:28 | INFO  | unit testing complete:

################################################################################
environment_tests
################################################################################

test_add_duplicates (environment_tests.SystemTests) ... ERROR
test_add_systems (environment_tests.SystemTests) ... ERROR
test_auto_add_systems (environment_tests.SystemTests) ... ERROR

======================================================================
ERROR: test_add_duplicates (environment_tests.SystemTests)
----------------------------------------------------------------------
Traceback (most recent call last):
  File "D:\osdt_dev\osdt_home\osdt_examples\osdt_testing\tests\environment_tests.py", line 21, in setUp
    osdt.enable_user_data(False)
AttributeError: module 'osdt' has no attribute 'enable_user_data'

======================================================================
ERROR: test_add_systems (environment_tests.SystemTests)
----------------------------------------------------------------------
Traceback (most recent call last):
  File "D:\osdt_dev\osdt_home\osdt_examples\osdt_testing\tests\environment_tests.py", line 21, in setUp
    osdt.enable_user_data(False)
AttributeError: module 'osdt' has no attribute 'enable_user_data'

======================================================================
ERROR: test_auto_add_systems (environment_tests.SystemTests)
----------------------------------------------------------------------
Traceback (most recent call last):
  File "D:\osdt_dev\osdt_home\osdt_examples\osdt_testing\tests\environment_tests.py", line 21, in setUp
    osdt.enable_user_data(False)
AttributeError: module 'osdt' has no attribute 'enable_user_data'

----------------------------------------------------------------------
Ran 3 tests in 0.001s

FAILED (errors=3)

################################################################################
fileio_tests
################################################################################

test_save_env (fileio_tests.SaveTests) ... ok
test_save_obj (fileio_tests.SaveTests) ... ok
test_load_env (fileio_tests.LoadTests) ... ok
test_load_obj (fileio_tests.LoadTests) ... ok
test_load_env (fileio_tests.LoadTestsBad) ... FAIL
test_load_obj (fileio_tests.LoadTestsBad) ... FAIL

======================================================================
FAIL: test_load_env (fileio_tests.LoadTestsBad)
----------------------------------------------------------------------
Traceback (most recent call last):
  File "D:\osdt_dev\osdt_home\osdt_examples\osdt_testing\tests\fileio_tests.py", line 65, in test_load_env
    self.compare_states(ball_state2, sys1.x())
  File "D:\osdt_dev\osdt_home\osdt_examples\osdt_testing\tests\fileio_tests.py", line 53, in compare_states
    self.assertEqual(orig.__dict__[key], loaded.__dict__[key])
AssertionError: 999.99 != 1.0

======================================================================
FAIL: test_load_obj (fileio_tests.LoadTestsBad)
----------------------------------------------------------------------
Traceback (most recent call last):
  File "D:\osdt_dev\osdt_home\osdt_examples\osdt_testing\tests\fileio_tests.py", line 59, in test_load_obj
    self.compare_states(orig,loaded)
  File "D:\osdt_dev\osdt_home\osdt_examples\osdt_testing\tests\fileio_tests.py", line 53, in compare_states
    self.assertEqual(orig.__dict__[key], loaded.__dict__[key])
AssertionError: 43243.0 != 1.0

----------------------------------------------------------------------
Ran 6 tests in 0.041s

FAILED (failures=2)

################################################################################
user_tests
################################################################################

test_auto_add_systems (user_tests.SystemTests) ... ok
test_manual_user_data_path (user_tests.SystemTests) ... ok

----------------------------------------------------------------------
Ran 2 tests in 0.045s

OK
 | tester.py:173
